{"uuid": "588d86e8-ece5-41c4-9603-528c888ca885", "children": ["29fcc004-4a18-4326-89c1-0afa6d3e1874"], "befores": [{"name": "connection_fixture", "status": "broken", "statusDetails": {"message": "websockets.exceptions.InvalidStatusCode: server rejected WebSocket connection: HTTP 429\n", "trace": "  File \"/home/krab/.local/lib/python3.6/site-packages/pluggy/callers.py\", line 187, in _multicall\n    res = hook_impl.function(*args)\n  File \"/home/krab/.local/lib/python3.6/site-packages/_pytest/fixtures.py\", line 958, in pytest_fixture_setup\n    result = call_fixture_func(fixturefunc, request, kwargs)\n  File \"/home/krab/.local/lib/python3.6/site-packages/_pytest/fixtures.py\", line 788, in call_fixture_func\n    res = fixturefunc(**kwargs)\n  File \"/home/krab/.local/lib/python3.6/site-packages/pytest_asyncio/plugin.py\", line 97, in wrapper\n    return loop.run_until_complete(setup())\n  File \"/usr/lib/python3.6/asyncio/base_events.py\", line 484, in run_until_complete\n    return future.result()\n  File \"/home/krab/.local/lib/python3.6/site-packages/pytest_asyncio/plugin.py\", line 78, in setup\n    res = await gen_obj.__anext__()\n  File \"/home/krab/PycharmProjects/bitfinex/websocket_API/conftest.py\", line 11, in connection_fixture\n    ws_connection = await websockets.connect(URI)\n  File \"/home/krab/.local/lib/python3.6/site-packages/websockets/client.py\", line 547, in __await_impl__\n    extra_headers=protocol.extra_headers,\n  File \"/home/krab/.local/lib/python3.6/site-packages/websockets/client.py\", line 296, in handshake\n    raise InvalidStatusCode(status_code)\n"}, "start": 1582626357473, "stop": 1582626357752}], "afters": [{"name": "connection_fixture::finalizer", "status": "passed", "start": 1582626357818, "stop": 1582626357819}], "start": 1582626357473, "stop": 1582626357819}